Workbook

Sheet gdp
A1: country | B1: quarter | C1: gdp_level
A2: AT | B2: 2000Q1 | C2: 61944.4
A3: AT | B3: 2000Q2 | C3: 62844.5
A4: AT | B4: 2000Q3 | C4: 63665.3
A5: AT | B5: 2000Q4 | C5: 64131.1
A6: AT | B6: 2001Q1 | C6: 63758.2
A7: AT | B7: 2001Q2 | C7: 63761.5
A8: AT | B8: 2001Q3 | C8: 63970.5
A9: AT | B9: 2001Q4 | C9: 64152.5
A10: AT | B10: 2002Q1 | C10: 64807.5
A11: AT | B11: 2002Q2 | C11: 64948.4
A12: AT | B12: 2002Q3 | C12: 65025.3
A13: AT | B13: 2002Q4 | C13: 64649.4
... A1061: PT | B1061: 2026Q2 | C1061: 54809.7

Sheet ict_inv
A1: country | B1: year | C1: N1132G | D1: N1173G | E1: N112G_secJ | F1: N117G_secJ | G1: N1173G_secJ | H1: N11G | I1: ict_share
A2: AT | B2: 2000 | C2: 3774.2 | D2: 3129.8 | E2: 421.5 | F2: 613.7 | G2: 424.8 | H2: 54601.4 | I2: =(C2+D2+E2+F2-G2)/H2 -> 0.13762284
A3: AT | B3: 2001 | C3: 3812.6 | D3: 3604.5 | E3: 268.9 | F3: 708.4 | G3: 486.4 | H3: 54685.2 | I3: =(C3+D3+E3+F3-G3)/H3 -> 0.14460951
A4: AT | B4: 2002 | C4: 3337.6 | D4: 3948.2 | E4: 211.5 | F4: 782 | G4: 542.9 | H4: 53172.7 | I4: =(C4+D4+E4+F4-G4)/H4 -> 0.14549571
A5: AT | B5: 2003 | C5: 3288.4 | D5: 3863.3 | E5: 68.8 | F5: 772.3 | G5: 520.3 | H5: 55777.6 | I5: =(C5+D5+E5+F5-G5)/H5 -> 0.13396955
A6: AT | B6: 2004 | C6: 3354.3 | D6: 3960.8 | E6: 80.6 | F6: 814.2 | G6: 533.8 | H6: 57172.6 | I6: =(C6+D6+E6+F6-G6)/H6 -> 0.13426187
A7: AT | B7: 2005 | C7: 3359.7 | D7: 3807.6 | E7: 81 | F7: 811.9 | G7: 516.4 | H7: 58633.6 | I7: =(C7+D7+E7+F7-G7)/H7 -> 0.12866002
A8: AT | B8: 2006 | C8: 3225 | D8: 4126.9 | E8: 62.9 | F8: 926.1 | G8: 585.6 | H8: 60714.5 | I8: =(C8+D8+E8+F8-G8)/H8 -> 0.1277339
A9: AT | B9: 2007 | C9: 3497.5 | D9: 4185.3 | E9: 159.1 | F9: 1030.9 | G9: 615.7 | H9: 65301.3 | I9: =(C9+D9+E9+F9-G9)/H9 -> 0.12644618
A10: AT | B10: 2008 | C10: 3839.2 | D10: 4491.8 | E10: 124.7 | F10: 1059.7 | G10: 656.9 | H10: 68682.5 | I10: =(C10+D10+E10+F10-G10)/H10 -> 0.12897754
A11: AT | B11: 2009 | C11: 3334.9 | D11: 4610.1 | E11: 119.8 | F11: 1418.3 | G11: 1062.9 | H11: 64880.3 | I11: =(C11+D11+E11+F11-G11)/H11 -> 0.12978053
A12: AT | B12: 2010 | C12: 3694.8 | D12: 4787.2 | E12: 49.8 | F12: 1441.8 | G12: 1005.3 | H12: 64282.9 | I12: =(C12+D12+E12+F12-G12)/H12 -> 0.139513
A13: AT | B13: 2011 | C13: 3792.1 | D13: 5830.1 | E13: 74.7 | F13: 1586.9 | G13: 1017.2 | H13: 69976.6 | I13: =(C13+D13+E13+F13-G13)/H13 -> 0.14671476
... A153: FR | B153: 2025 | C153: 13311.3 | D153: 97013.8 | E153: 2636.1 | F153: 29020.9 | G153: 20445.8 | H153: 663584.6 | I153: =(C153+D153+E153+F153-G153)/H153 -> 0.18315118
A154: IE | B154: 2000 | C154: 1204.4 | D154: 460.3 | E154: 217.7 | F154: 470.5 | H154: 25759 | I154: =(C154+D154+E154+F154-G154)/H154 -> 0.091342832
A155: IE | B155: 2001 | C155: 1088.8 | D155: 647.9 | E155: 254.9 | F155: 936.4 | H155: 29223.7 | I155: =(C155+D155+E155+F155-G155)/H155 -> 0.10019265
A156: IE | B156: 2002 | C156: 915.5 | D156: 571.6 | E156: 290.2 | F156: 1263 | H156: 32086.1 | I156: =(C156+D156+E156+F156-G156)/H156 -> 0.094754426
A157: IE | B157: 2003 | C157: 820.1 | D157: 607.9 | E157: 294.8 | F157: 1227.9 | H157: 36264.8 | I157: =(C157+D157+E157+F157-G157)/H157 -> 0.081365401
A158: IE | B158: 2004 | C158: 888.6 | D158: 676.9 | E158: 307.6 | F158: 1554.8 | H158: 42112.5 | I158: =(C158+D158+E158+F158-G158)/H158 -> 0.081398635
A159: IE | B159: 2005 | C159: 795.1 | D159: 703.6 | E159: 277.4 | F159: 1436.7 | H159: 50800.7 | I159: =(C159+D159+E159+F159-G159)/H159 -> 0.063243223
A160: IE | B160: 2006 | C160: 1072.6 | D160: 776.6 | E160: 343 | F160: 1672.1 | H160: 57299.4 | I160: =(C160+D160+E160+F160-G160)/H160 -> 0.067440497
A161: IE | B161: 2007 | C161: 1335.7 | D161: 919.9 | E161: 379.3 | F161: 1587.9 | H161: 56572.9 | I161: =(C161+D161+E161+F161-G161)/H161 -> 0.074643513
A162: IE | B162: 2008 | C162: 1136.5 | D162: 920.5 | E162: 448.1 | F162: 1927.2 | H162: 46525.1 | I162: =(C162+D162+E162+F162-G162)/H162 -> 0.095266856
A163: IE | B163: 2009 | C163: 1166.7 | D163: 910 | E163: 217.7 | F163: 2313.5 | H163: 35875.7 | I163: =(C163+D163+E163+F163-G163)/H163 -> 0.1284407
A164: IE | B164: 2010 | C164: 1156.9 | D164: 1037.5 | E164: 344.1 | F164: 2505.3 | H164: 29422.5 | I164: =(C164+D164+E164+F164-G164)/H164 -> 0.17142663
A165: IE | B165: 2011 | C165: 1986 | D165: 1087.2 | E165: 324.2 | F165: 2708.2 | H165: 28677.5 | I165: =(C165+D165+E165+F165-G165)/H165 -> 0.21290559
... A179: IE | B179: 2025 | C179: 5187.1 | D179: 6876.3 | E179: 886 | F179: 23845.9 | H179: 145261.1 | I179: =(C179+D179+E179+F179-G179)/H179 -> 0.25330457
A180: IT | B180: 2000 | C180: 13266.4 | D180: 17549.5 | E180: 1574.4 | F180: 6378.8 | G180: 4518.1 | H180: 264206.4 | I180: =(C180+D180+E180+F180-G180)/H180 -> 0.12963728
A181: IT | B181: 2001 | C181: 12798.5 | D181: 18903 | E181: 2331.2 | F181: 6522.9 | G181: 4728.8 | H181: 277322 | I181: =(C181+D181+E181+F181-G181)/H181 -> 0.12918845
A182: IT | B182: 2002 | C182: 12997.1 | D182: 19853.3 | E182: 1600.3 | F182: 6729.4 | G182: 4861.7 | H182: 295667.7 | I182: =(C182+D182+E182+F182-G182)/H182 -> 0.1228352
A183: IT | B183: 2003 | C183: 12188.5 | D183: 19090.9 | E183: 1785.2 | F183: 7396.5 | G183: 5403.5 | H183: 297848.6 | I183: =(C183+D183+E183+F183-G183)/H183 -> 0.11770275
A184: IT | B184: 2004 | C184: 13790.2 | D184: 18144.7 | E184: 1939.1 | F184: 6459.1 | G184: 4395 | H184: 311288.4 | I184: =(C184+D184+E184+F184-G184)/H184 -> 0.11544953
A185: IT | B185: 2005 | C185: 14574.4 | D185: 18591.8 | E185: 2421.4 | F185: 6782.8 | G185: 4694.2 | H185: 324900.7 | I185: =(C185+D185+E185+F185-G185)/H185 -> 0.1159622
A186: IT | B186: 2006 | C186: 13499.2 | D186: 19057.2 | E186: 2373.7 | F186: 6760.6 | G186: 4632.4 | H186: 341988.4 | I186: =(C186+D186+E186+F186-G186)/H186 -> 0.10836128
A187: IT | B187: 2007 | C187: 13967.5 | D187: 20015 | E187: 2278.8 | F187: 7594.4 | G187: 5222.3 | H187: 356687.6 | I187: =(C187+D187+E187+F187-G187)/H187 -> 0.10831159
A188: IT | B188: 2008 | C188: 13209.2 | D188: 19877.7 | E188: 1909.9 | F188: 7504.2 | G188: 4971.9 | H188: 354419.4 | I188: =(C188+D188+E188+F188-G188)/H188 -> 0.10588896
A189: IT | B189: 2009 | C189: 11088.7 | D189: 19211.2 | E189: 1515.2 | F189: 7071.5 | G189: 4417.3 | H189: 321826.5 | I189: =(C189+D189+E189+F189-G189)/H189 -> 0.10710523
A190: IT | B190: 2010 | C190: 13344.3 | D190: 19721.9 | E190: 1988.3 | F190: 7568.8 | G190: 4839.5 | H190: 327450.4 | I190: =(C190+D190+E190+F190-G190)/H190 -> 0.11538786
A191: IT | B191: 2011 | C191: 13490.8 | D191: 19015.5 | E191: 2136.4 | F191: 7303.5 | G191: 4703.5 | H191: 329961.7 | I191: =(C191+D191+E191+F191-G191)/H191 -> 0.11286977
... A231: NL | B231: 2025 | C231: 9842 | D231: 26717 | E231: 3224 | F231: 4604 | G231: 2672 | H231: 235432 | I231: =(C231+D231+E231+F231-G231)/H231 -> 0.17718492
...

Sheet ai_patent
A1: country | B1: year | C1: ai_patents
A2: AT | B2: 2015 | C2: 3
A3: AT | B3: 2016 | C3: 10
A4: AT | B4: 2017 | C4: 11
A5: AT | B5: 2018 | C5: 12
A6: AT | B6: 2019 | C6: 6
A7: AT | B7: 2020 | C7: 15
A8: AT | B8: 2021 | C8: 15
A9: AT | B9: 2022 | C9: 9
A10: AT | B10: 2023 | C10: 1
A11: AT | B11: 2024 | C11: 0
A12: AT | B12: 2025 | C12: 0
A13: BE | B13: 2015 | C13: 0
... A111: PT | B111: 2025 | C111: 0

Sheet ai_inv
A1: country | B1: year | C1: ai_investment | D1: share
A2: AT | B2: 2015 | C2: 3 | D2: =(C2/gdp!C65)*1000 -> 0.03841003
A3: AT | B3: 2016 | C3: 21 | D3: =(C3/gdp!C69)*1000 -> 0.2629368
A4: AT | B4: 2017 | C4: 24 | D4: =(C4/gdp!C73)*1000 -> 0.29320354
A5: AT | B5: 2018 | C5: 39 | D5: =(C5/gdp!C77)*1000 -> 0.46313944
A6: AT | B6: 2019 | C6: 43 | D6: =(C6/gdp!C81)*1000 -> 0.51040999
A7: AT | B7: 2020 | C7: 47 | D7: =(C7/gdp!C85)*1000 -> 0.58820879
A8: AT | B8: 2021 | C8: 67 | D8: =(C8/gdp!C89)*1000 -> 0.78313936
A9: AT | B9: 2022 | C9: 68 | D9: =(C9/gdp!C93)*1000 -> 0.77089814
A10: AT | B10: 2023 | C10: 149 | D10: =(C10/gdp!C97)*1000 -> 1.7201729
A11: AT | B11: 2024 | C11: 133 | D11: =(C11/gdp!C101)*1000 -> 1.530752
A12: AT | B12: 2025 | C12: 75 | D12: =(C12/gdp!C105)*1000 -> 0.85368908
A13: BE | B13: 2015 | C13: 38 | D13: =(C13/gdp!C171)*1000 -> 0.39371506
A14: BE | B14: 2016 | C14: 12 | D14: =(C14/gdp!C175)*1000 -> 0.12278363
A15: BE | B15: 2017 | C15: 54 | D15: =(C15/gdp!C179)*1000 -> 0.54390414
A16: BE | B16: 2018 | C16: 26 | D16: =(C16/gdp!C183)*1000 -> 0.25601336
A17: BE | B17: 2019 | C17: 30 | D17: =(C17/gdp!C187)*1000 -> 0.28857836
A18: BE | B18: 2020 | C18: 70 | D18: =(C18/gdp!C191)*1000 -> 0.69919523
A19: BE | B19: 2021 | C19: 65 | D19: =(C19/gdp!C195)*1000 -> 0.61145107
A20: BE | B20: 2022 | C20: 79 | D20: =(C20/gdp!C199)*1000 -> 0.72263059
A21: BE | B21: 2023 | C21: 61 | D21: =(C21/gdp!C203)*1000 -> 0.55195078
A22: BE | B22: 2024 | C22: 97 | D22: =(C22/gdp!C207)*1000 -> 0.86948182
A23: BE | B23: 2025 | C23: 121 | D23: =(C23/gdp!C211)*1000 -> 1.074587
A24: DE | B24: 2015 | C24: 106 | D24: =(C24/gdp!C277)*1000 -> 0.14767369
A25: DE | B25: 2016 | C25: 168 | D25: =(C25/gdp!C281)*1000 -> 0.22940969
A26: DE | B26: 2017 | C26: 245 | D26: =(C26/gdp!C285)*1000 -> 0.32172079
A27: DE | B27: 2018 | C27: 265 | D27: =(C27/gdp!C289)*1000 -> 0.34755507
A28: DE | B28: 2019 | C28: 389 | D28: =(C28/gdp!C293)*1000 -> 0.50617356
A29: DE | B29: 2020 | C29: 404 | D29: =(C29/gdp!C297)*1000 -> 0.53632279
A30: DE | B30: 2021 | C30: 710 | D30: =(C30/gdp!C301)*1000 -> 0.92018115
A31: DE | B31: 2022 | C31: 886 | D31: =(C31/gdp!C305)*1000 -> 1.1381739
A32: DE | B32: 2023 | C32: 846 | D32: =(C32/gdp!C309)*1000 -> 1.0970433
A33: DE | B33: 2024 | C33: 791 | D33: =(C33/gdp!C313)*1000 -> 1.0215985
A34: DE | B34: 2025 | C34: 818 | D34: =(C34/gdp!C317)*1000 -> 1.0529127
A35: ES | B35: 2015 | C35: 67 | D35: =(C35/gdp!C383)*1000 -> 0.24412541
A36: ES | B36: 2016 | C36: 91 | D36: =(C36/gdp!C387)*1000 -> 0.32378661
A37: ES | B37: 2017 | C37: 89 | D37: =(C37/gdp!C391)*1000 -> 0.3073647
A38: ES | B38: 2018 | C38: 109 | D38: =(C38/gdp!C395)*1000 -> 0.36818229
A39: ES | B39: 2019 | C39: 138 | D39: =(C39/gdp!C399)*1000 -> 0.45846719
A40: ES | B40: 2020 | C40: 161 | D40: =(C40/gdp!C403)*1000 -> 0.58774375
...

Sheet index_nat
A1: country | B1: ticker | C1: quarter | D1: close | E1: log_ret
A2: NL | B2: ^AEX | C2: 2000Q1 | D2: 662.28998
A3: NL | B3: ^AEX | C3: 2000Q2 | D3: 672.14001 | E3: 0.014763181
A4: NL | B4: ^AEX | C4: 2000Q3 | D4: 661.52002 | E4: -0.015926427
A5: NL | B5: ^AEX | C5: 2000Q4 | D5: 637.59998 | E5: -0.036829158
A6: NL | B6: ^AEX | C6: 2001Q1 | D6: 558.35999 | E6: -0.1327072
A7: NL | B7: ^AEX | C7: 2001Q2 | D7: 573.5 | E7: 0.026754047
A8: NL | B8: ^AEX | C8: 2001Q3 | D8: 453.87 | E8: -0.23394713
A9: NL | B9: ^AEX | C9: 2001Q4 | D9: 506.78 | E9: 0.11026618
A10: NL | B10: ^AEX | C10: 2002Q1 | D10: 531.21002 | E10: 0.047080483
A11: NL | B11: ^AEX | C11: 2002Q2 | D11: 439.66 | E11: -0.18915576
A12: NL | B12: ^AEX | C12: 2002Q3 | D12: 296.35999 | E12: -0.39442683
A13: NL | B13: ^AEX | C13: 2002Q4 | D13: 322.73001 | E13: 0.085241212
A14: NL | B14: ^AEX | C14: 2003Q1 | D14: 248.53999 | E14: -0.26121232
... A109: NL | B109: ^AEX | C109: 2026Q4 | D109: 1124.36 | E109: 0.0084492352
A110: DE | B110: ^GDAXI | C110: 2000Q1 | D110: 7599.3901
A111: DE | B111: ^GDAXI | C111: 2000Q2 | D111: 6898.21 | E111: -0.096806047
A112: DE | B112: ^GDAXI | C112: 2000Q3 | D112: 6798.1201 | E112: -0.014615831
A113: DE | B113: ^GDAXI | C113: 2000Q4 | D113: 6433.6099 | E113: -0.05511033
A114: DE | B114: ^GDAXI | C114: 2001Q1 | D114: 5829.9502 | E114: -0.098527333
A115: DE | B115: ^GDAXI | C115: 2001Q2 | D115: 6058.3799 | E115: 0.038433961
A116: DE | B116: ^GDAXI | C116: 2001Q3 | D116: 4308.1499 | E116: -0.34093386
A117: DE | B117: ^GDAXI | C117: 2001Q4 | D117: 5160.1001 | E117: 0.18044742
A118: DE | B118: ^GDAXI | C118: 2002Q1 | D118: 5397.29 | E118: 0.044941005
A119: DE | B119: ^GDAXI | C119: 2002Q2 | D119: 4382.5601 | E119: -0.20826394
A120: DE | B120: ^GDAXI | C120: 2002Q3 | D120: 2769.03 | E120: -0.45913595
A121: DE | B121: ^GDAXI | C121: 2002Q4 | D121: 2892.6299 | E121: 0.043668993
A122: DE | B122: ^GDAXI | C122: 2003Q1 | D122: 2423.8701 | E122: -0.1768006
... A217: DE | B217: ^GDAXI | C217: 2026Q4 | D217: 25248.631 | E217: 0.0019601014
A218: FR | B218: ^FCHI | C218: 2000Q1 | D218: 6286.0498
A219: FR | B219: ^FCHI | C219: 2000Q2 | D219: 6446.54 | E219: 0.025210697
A220: FR | B220: ^FCHI | C220: 2000Q3 | D220: 6266.6299 | E220: -0.028304847
A221: FR | B221: ^FCHI | C221: 2000Q4 | D221: 5926.4199 | E221: -0.055818404
A222: FR | B222: ^FCHI | C222: 2001Q1 | D222: 5180.4502 | E222: -0.13452834
A223: FR | B223: ^FCHI | C223: 2001Q2 | D223: 5225.3301 | E223: 0.0086260059
A224: FR | B224: ^FCHI | C224: 2001Q3 | D224: 4079.02 | E224: -0.2476612
A225: FR | B225: ^FCHI | C225: 2001Q4 | D225: 4624.5801 | E225: 0.1255288
A226: FR | B226: ^FCHI | C226: 2002Q1 | D226: 4688.02 | E226: 0.01362475
A227: FR | B227: ^FCHI | C227: 2002Q2 | D227: 3897.99 | E227: -0.18454929
A228: FR | B228: ^FCHI | C228: 2002Q3 | D228: 2777.45 | E228: -0.33892781
...

Sheet index_sox
A1: ticker | B1: quarter | C1: close | D1: log_ret
A2: ^SOX | B2: 2000Q1 | C2: 1181.3184
A3: ^SOX | B3: 2000Q2 | C3: 1139.9784 | D3: -0.035621759
A4: ^SOX | B4: 2000Q3 | C4: 851.15814 | D4: -0.29216665
A5: ^SOX | B5: 2000Q4 | C5: 576.33112 | D5: -0.38991559
A6: ^SOX | B6: 2001Q1 | C6: 544.77637 | D6: -0.056306974
A7: ^SOX | B7: 2001Q2 | C7: 623.78821 | D7: 0.13543553
A8: ^SOX | B8: 2001Q3 | C8: 373.51929 | D8: -0.51284126
A9: ^SOX | B9: 2001Q4 | C9: 521.90741 | D9: 0.33452055
A10: ^SOX | B10: 2002Q1 | C10: 594.95209 | D10: 0.13099068
A11: ^SOX | B11: 2002Q2 | C11: 387.39255 | D11: -0.42904236
A12: ^SOX | B12: 2002Q3 | C12: 238.12479 | D12: -0.48664367
A13: ^SOX | B13: 2002Q4 | C13: 289.1001 | D13: 0.19397814
A14: ^SOX | B14: 2003Q1 | C14: 296.12671 | D14: 0.024014447
... A109: ^SOX | B109: 2026Q4 | C109: 13217.82 | D109: 0.045600267

Sheet index_msci
A1: ticker | B1: quarter | C1: close | D1: log_ret
A2: ^990100-USD-STRD | B2: 2000Q1 | C2: 1419.5
A3: ^990100-USD-STRD | B3: 2000Q2 | C3: 1366.2 | D3: -0.038271569
A4: ^990100-USD-STRD | B4: 2000Q3 | C4: 1312.4 | D4: -0.040175587
A5: ^990100-USD-STRD | B5: 2000Q4 | C5: 1228.5 | D5: -0.066063628
A6: ^990100-USD-STRD | B6: 2001Q1 | C6: 1055.2 | D6: -0.15206364
A7: ^990100-USD-STRD | B7: 2001Q2 | C7: 1086.6 | D7: 0.029323257
A8: ^990100-USD-STRD | B8: 2001Q3 | C8: 925.70001 | D8: -0.16025859
A9: ^990100-USD-STRD | B9: 2001Q4 | C9: 1003.1 | D9: 0.080300238
A10: ^990100-USD-STRD | B10: 2002Q1 | C10: 1003.6 | D10: 0.00049833061
A11: ^990100-USD-STRD | B11: 2002Q2 | C11: 909.29999 | D11: -0.098673731
A12: ^990100-USD-STRD | B12: 2002Q3 | C12: 737.79999 | D12: -0.20900229
A13: ^990100-USD-STRD | B13: 2002Q4 | C13: 792.40002 | D13: 0.071393577
A14: ^990100-USD-STRD | B14: 2003Q1 | C14: 766.59998 | D14: -0.033101225
... A109: ^990100-USD-STRD | B109: 2026Q4 | C109: 4974.4199 | D109: 0.014522652

Sheet index_stoxx600
A1: ticker | B1: quarter | C1: close | D1: log_ret | E1: source
A2: ^STOXX (proxied via ^GDAXI) | B2: 2000Q1 | C2: 451.64349 | E2: DAX_proxy
A3: ^STOXX (proxied via ^GDAXI) | B3: 2000Q2 | C3: 409.97127 | D3: -0.096806047 | E3: DAX_proxy
A4: ^STOXX (proxied via ^GDAXI) | B4: 2000Q3 | C4: 404.02278 | D4: -0.014615831 | E4: DAX_proxy
A5: ^STOXX (proxied via ^GDAXI) | B5: 2000Q4 | C5: 382.35937 | D5: -0.05511033 | E5: DAX_proxy
A6: ^STOXX (proxied via ^GDAXI) | B6: 2001Q1 | C6: 346.48294 | D6: -0.098527333 | E6: DAX_proxy
A7: ^STOXX (proxied via ^GDAXI) | B7: 2001Q2 | C7: 360.05887 | D7: 0.038433961 | E7: DAX_proxy
A8: ^STOXX (proxied via ^GDAXI) | B8: 2001Q3 | C8: 256.04 | D8: -0.34093386 | E8: DAX_proxy
A9: ^STOXX (proxied via ^GDAXI) | B9: 2001Q4 | C9: 306.67272 | D9: 0.18044742 | E9: DAX_proxy
A10: ^STOXX (proxied via ^GDAXI) | B10: 2002Q1 | C10: 320.76928 | D10: 0.044941005 | E10: DAX_proxy
A11: ^STOXX (proxied via ^GDAXI) | B11: 2002Q2 | C11: 260.46231 | D11: -0.20826394 | E11: DAX_proxy
A12: ^STOXX (proxied via ^GDAXI) | B12: 2002Q3 | C12: 164.56773 | D12: -0.45913595 | E12: DAX_proxy
A13: ^STOXX (proxied via ^GDAXI) | B13: 2002Q4 | C13: 171.91346 | D13: 0.043668993 | E13: DAX_proxy
A14: ^STOXX (proxied via ^GDAXI) | B14: 2003Q1 | C14: 144.05434 | D14: -0.1768006 | E14: DAX_proxy
... A18: ^STOXX (proxied via ^GDAXI) | B18: 2004Q1 | C18: 229.20963 | D18: -0.027734302 | E18: DAX_proxy
A19: ^STOXX | B19: 2004Q2 | C19: 240.86 | E19: STOXX600
A20: ^STOXX | B20: 2004Q3 | C20: 237.74001 | D20: -0.013038192 | E20: STOXX600
A21: ^STOXX | B21: 2004Q4 | C21: 251.02 | D21: 0.054354972 | E21: STOXX600
A22: ^STOXX | B22: 2005Q1 | C22: 262.19 | D22: 0.043536807 | E22: STOXX600
A23: ^STOXX | B23: 2005Q2 | C23: 275.92001 | D23: 0.051041576 | E23: STOXX600
A24: ^STOXX | B24: 2005Q3 | C24: 297.39999 | D24: 0.074966996 | E24: STOXX600
A25: ^STOXX | B25: 2005Q4 | C25: 310.03 | D25: 0.04159105 | E25: STOXX600
A26: ^STOXX | B26: 2006Q1 | C26: 334.44 | D26: 0.075788436 | E26: STOXX600
A27: ^STOXX | B27: 2006Q2 | C27: 320.66 | D27: -0.042076115 | E27: STOXX600
A28: ^STOXX | B28: 2006Q3 | C28: 341.42999 | D28: 0.062761275 | E28: STOXX600
A29: ^STOXX | B29: 2006Q4 | C29: 365.26001 | D29: 0.067466797 | E29: STOXX600
A30: ^STOXX | B30: 2007Q1 | C30: 374.22 | D30: 0.024234408 | E30: STOXX600
A31: ^STOXX | B31: 2007Q2 | C31: 393.70999 | D31: 0.050770713 | E31: STOXX600
... A109: ^STOXX | B109: 2026Q4 | C109: 633.84003 | D109: -0.0016551796 | E109: STOXX600

Sheet hs_export
A1: country | B1: year | C1: HS_847150 | D1: HS_847180 | E1: HS_847330 | F1: HS_848610 | G1: HS_848620 | H1: HS_848630 | I1: HS_848640 | J1: HS_848690 | K1: total_export | L1: share
A2: AT | B2: 2002 | C2: 38846168 | D2: 19334560 | E2: 557336676 | K2: 83198982398 | L2: =SUM(C2:J2)/K2 -> 0.0073981362
A3: AT | B3: 2003 | C3: 188407673 | D3: 26998864 | E3: 399933931 | K3: 85878805465 | L3: =SUM(C3:J3)/K3 -> 0.0071652192
A4: AT | B4: 2004 | C4: 231878639 | D4: 50228317 | E4: 424954628 | K4: 95164850432 | L4: =SUM(C4:J4)/K4 -> 0.0074298607
A5: AT | B5: 2005 | C5: 50434737 | D5: 47674743 | E5: 521799897 | K5: 100620644589 | L5: =SUM(C5:J5)/K5 -> 0.0061608567
A6: AT | B6: 2006 | C6: 48711706 | D6: 57555760 | E6: 585441741 | K6: 108913131868 | L6: =SUM(C6:J6)/K6 -> 0.0063510175
A7: AT | B7: 2007 | C7: 67522767 | D7: 57481400 | E7: 582514360 | F7: 152499984 | G7: 47302411 | H7: 4057385 | I7: 47609001 | J7: 69054273 | K7: 119387392490 | L7: =SUM(C7:J7)/K7 -> 0.0086109727
A8: AT | B8: 2008 | C8: 54566625 | D8: 63669760 | E8: 360457364 | F8: 61894877 | G8: 54960745 | H8: 281212 | I8: 54079746 | J8: 44625149 | K8: 123258767441 | L8: =SUM(C8:J8)/K8 -> 0.0056347755
A9: AT | B9: 2009 | C9: 39403070 | D9: 34860552 | E9: 330631700 | F9: 17337421 | G9: 138568915 | H9: 3094269 | I9: 31537573 | J9: 36234425 | K9: 98213743491 | L9: =SUM(C9:J9)/K9 -> 0.0064315635
A10: AT | B10: 2010 | C10: 57824890 | D10: 36741826 | E10: 323991909 | F10: 8945630 | G10: 232274669 | H10: 1188294 | I10: 45077274 | J10: 74938243 | K10: 115078517863 | L10: =SUM(C10:J10)/K10 -> 0.0067865206
A11: AT | B11: 2011 | C11: 58781521 | D11: 35534590 | E11: 310394404 | F11: 9981485 | G11: 217226219 | H11: 561343 | I11: 57514215 | J11: 106575051 | K11: 127462352596 | L11: =SUM(C11:J11)/K11 -> 0.0062494439
A12: AT | B12: 2012 | C12: 115111470 | D12: 33576833 | E12: 197188753 | F12: 14313064 | G12: 229290820 | H12: 273016 | I12: 41863801 | J12: 91876583 | K12: 129678513652 | L12: =SUM(C12:J12)/K12 -> 0.0055791381
A13: AT | B13: 2013 | C13: 162267515 | D13: 33030676 | E13: 157917799 | F13: 9936014 | G13: 230961180 | H13: 161543 | I13: 33699223 | J13: 93198464 | K13: 131884592219 | L13: =SUM(C13:J13)/K13 -> 0.0054682082
A14: AT | B14: 2014 | C14: 150117604 | D14: 53899692 | E14: 210014639 | F14: 10389758 | G14: 232010017 | H14: 4219 | I14: 38596276 | J14: 97980890 | K14: 134172544432 | L14: =SUM(C14:J14)/K14 -> 0.0059103977
A15: AT | B15: 2015 | C15: 108569916 | D15: 23217601 | E15: 199326295 | F15: 11111667 | G15: 333159906 | H15: 2554 | I15: 50855232 | J15: 133722341 | K15: 137756781413 | L15: =SUM(C15:J15)/K15 -> 0.0062426365
A16: AT | B16: 2016 | C16: 120201047 | D16: 42752787 | E16: 202143574 | F16: 10945914 | G16: 285145189 | H16: 152410 | I16: 47743495 | J16: 99284711 | K16: 137409879273 | L16: =SUM(C16:J16)/K16 -> 0.005882904
A17: AT | B17: 2017 | C17: 121853376 | D17: 34870914 | E17: 177162483 | F17: 14117224 | G17: 332980102 | H17: 4037 | I17: 59124825 | J17: 93781436 | K17: 148756390257 | L17: =SUM(C17:J17)/K17 -> 0.0056057719
A18: AT | B18: 2018 | C18: 124758012 | D18: 38836888 | E18: 161849712 | F18: 17815535 | G18: 441264446 | H18: 486 | I18: 71813097 | J18: 113530813 | K18: 156428829131 | L18: =SUM(C18:J18)/K18 -> 0.0062000655
... A24: AT | B24: 2024 | C24: 215805701 | D24: 33431885 | E24: 145224755 | F24: 4060484 | G24: 1417235685 | H24: 1944 | I24: 65261819 | J24: 283202931 | K24: 197847661904 | L24: =SUM(C24:J24)/K24 -> 0.010938847
A25: AT | B25: 2025 | C25: 178293386 | D25: 47402583 | E25: 118061295 | F25: 1993352 | G25: 1709849629 | I25: 48738750 | J25: 293158041 | K25: 196683124240 | L25: =SUM(C25:J25)/K25 -> 0.012189643
A26: BE | B26: 2002 | C26: 135921980 | D26: 171838652 | E26: 1185200958 | K26: 228561124588 | L26: =SUM(C26:J26)/K26 -> 0.0065320014
A27: BE | B27: 2003 | C27: 110247561 | D27: 96255997 | E27: 1246148612 | K27: 225969572236 | L27: =SUM(C27:J27)/K27 -> 0.00642853
A28: BE | B28: 2004 | C28: 82395153 | D28: 137489782 | E28: 1160570045 | K28: 246697039899 | L28: =SUM(C28:J28)/K28 -> 0.0055957501
A29: BE | B29: 2005 | C29: 78839876 | D29: 193339293 | E29: 1369088396 | K29: 268788791206 | L29: =SUM(C29:J29)/K29 -> 0.0061061607
A30: BE | B30: 2006 | C30: 69297038 | D30: 227317321 | E30: 1337975543 | K30: 292087129343 | L30: =SUM(C30:J30)/K30 -> 0.0055962408
A31: BE | B31: 2007 | C31: 72764243 | D31: 229264853 | E31: 301753553 | F31: 613980 | G31: 4364671 | H31: 4287712 | I31: 1408274 | J31: 17274414 | K31: 314448682983 | L31: =SUM(C31:J31)/K31 -> 0.0020090137
A32: BE | B32: 2008 | C32: 112600465 | D32: 200991891 | E32: 413861240 | F32: 468632 | G32: 13698763 | H32: 5990734 | I32: 1523171 | J32: 10437445 | K32: 320805175917 | L32: =SUM(C32:J32)/K32 -> 0.002367706
A33: BE | B33: 2009 | C33: 93562225 | D33: 149820419 | E33: 311461973 | F33: 821007 | G33: 1605789 | H33: 7116923 | I33: 991851 | J33: 4706336 | K33: 265986039448 | L33: =SUM(C33:J33)/K33 -> 0.0021432949
A34: BE | B34: 2010 | C34: 99935483 | D34: 155840432 | E34: 290024469 | F34: 586061 | G34: 8916034 | H34: 6722973 | I34: 2253673 | J34: 5367271 | K34: 307529865750 | L34: =SUM(C34:J34)/K34 -> 0.0018523287
A35: BE | B35: 2011 | C35: 99772191 | D35: 144941674 | E35: 318080136 | F35: 1053694 | G35: 2549142 | H35: 6985620 | I35: 2845231 | J35: 11833833 | K35: 341718212953 | L35: =SUM(C35:J35)/K35 -> 0.001720896
A36: BE | B36: 2012 | C36: 108746044 | D36: 141886093 | E36: 328246921 | F36: 420541 | G36: 22405610 | H36: 4558920 | I36: 2369202 | J36: 11010049 | K36: 347088552540 | L36: =SUM(C36:J36)/K36 -> 0.0017852602
A37: BE | B37: 2013 | C37: 150056804 | D37: 114161772 | E37: 269847958 | F37: 209953 | G37: 22994684 | H37: 2935651 | I37: 1701466 | J37: 6686277 | K37: 352955703712 | L37: =SUM(C37:J37)/K37 -> 0.0016109516
A38: BE | B38: 2014 | C38: 190970853 | D38: 99617732 | E38: 192463171 | F38: 264319 | G38: 23478532 | H38: 3394501 | I38: 269674 | J38: 4322462 | K38: 355287706297 | L38: =SUM(C38:J38)/K38 -> 0.0014489138
A39: BE | B39: 2015 | C39: 340634900 | D39: 95865399 | E39: 241767904 | F39: 1279056 | G39: 7875239 | H39: 920246 | I39: 674644 | J39: 11625716 | K39: 357771767156 | L39: =SUM(C39:J39)/K39 -> 0.0019583521
A40: BE | B40: 2016 | C40: 283292850 | D40: 103120114 | E40: 203490879 | F40: 957428 | G40: 15093444 | H40: 32391 | I40: 577153 | J40: 16210145 | K40: 359757326643 | L40: =SUM(C40:J40)/K40 -> 0.0017310958
A41: BE | B41: 2017 | C41: 190464037 | D41: 89780745 | E41: 201554002 | F41: 44971 | G41: 11960445 | H41: 15475 | I41: 1112637 | J41: 24137394 | K41: 380590405102 | L41: =SUM(C41:J41)/K41 -> 0.0013638539
A42: BE | B42: 2018 | C42: 91713086 | D42: 94681834 | E42: 153952678 | F42: 151048 | G42: 11424356 | H42: 5610 | I42: 924827 | J42: 23515179 | K42: 396270037460 | L42: =SUM(C42:J42)/K42 -> 0.00094977814
... A49: BE | B49: 2025 | C49: 286361705 | D49: 247496360 | E49: 268391204 | F49: 1018809 | G49: 17967748 | H49: 90432 | I49: 1429249 | J49: 61447712 | K49: 505930348885 | L49: =SUM(C49:J49)/K49 -> 0.0017476778
A50: DE | B50: 2002 | C50: 2321522154 | D50: 473171387 | E50: 5509713187 | K50: 651259219283 | L50: =SUM(C50:J50)/K50 -> 0.012751308
A51: DE | B51: 2003 | C51: 3130190879 | D51: 619170855 | E51: 5535873439 | K51: 664391897584 | L51: =SUM(C51:J51)/K51 -> 0.013975539
...

Sheet eur_export
A1: country | B1: year | C1: CPA_261_intra | D1: CPA_261_extra | E1: CPA_262_intra | F1: CPA_262_extra | G1: CPA_2899_intra | H1: CPA_2899_extra | I1: total_export_intra | J1: total_export_extra | K1: share
A2: AT | B2: 2002 | C2: 1352970368 | D2: 504525916 | E2: 1050392413 | F2: 424877211 | G2: 272694726 | H2: 377436046 | I2: 51087208382 | J2: 23951472573 | K2: =SUM(C2:H2)/(I2+J2) -> 0.053077914
A3: AT | B3: 2003 | C3: 1314284036 | D3: 392361518 | E3: 1057292411 | F3: 396464007 | G3: 289045216 | H3: 348750681 | I3: 52785493285 | J3: 24229583798 | K3: =SUM(C3:H3)/(I3+J3) -> 0.049317588
A4: AT | B4: 2004 | C4: 1504953676 | D4: 516012407 | E4: 1381763681 | F4: 725785098 | G4: 390540891 | H4: 477753468 | I4: 64540989304 | J4: 27959308445 | K4: =SUM(C4:H4)/(I4+J4) -> 0.054019385
A5: AT | B5: 2005 | C5: 1575723005 | D5: 593767867 | E5: 1060017068 | F5: 714475915 | G5: 470708917 | H5: 473541210 | I5: 69922360334 | J5: 31075568021 | K5: =SUM(C5:H5)/(I5+J5) -> 0.048399349
A6: AT | B6: 2006 | C6: 1809024531 | D6: 756796395 | E6: 1031691758 | F6: 379737810 | G6: 441936541 | H6: 524540609 | I6: 75791886427 | J6: 33297773096 | K6: =SUM(C6:H6)/(I6+J6) -> 0.045318022
A7: AT | B7: 2007 | C7: 1439230344 | D7: 568132058 | E7: 1030841586 | F7: 405443083 | G7: 893944983 | H7: 754727776 | I7: 86645228493 | J7: 35483645232 | K7: =SUM(C7:H7)/(I7+J7) -> 0.041696281
A8: AT | B8: 2008 | C8: 1195752529 | D8: 695688326 | E8: 1122316434 | F8: 333000480 | G8: 897230750 | H8: 770767458 | I8: 89023575963 | J8: 36568410366 | K8: =SUM(C8:H8)/(I8+J8) -> 0.039928949
A9: AT | B9: 2009 | C9: 949160956 | D9: 499148626 | E9: 929892110 | F9: 226856261 | G9: 663087502 | H9: 671608796 | I9: 70376088768 | J9: 29773633074 | K9: =SUM(C9:H9)/(I9+J9) -> 0.039338644
A10: AT | B10: 2010 | C10: 1357254710 | D10: 782364990 | E10: 1068219526 | F10: 247974175 | G10: 741447612 | H10: 794131632 | I10: 82004481667 | J10: 35474835106 | K10: =SUM(C10:H10)/(I10+J10) -> 0.042487416
A11: AT | B11: 2011 | C11: 1153045756 | D11: 859322315 | E11: 779369155 | F11: 326789437 | G11: 864481109 | H11: 888547593 | I11: 89797308300 | J11: 40277174577 | K11: =SUM(C11:H11)/(I11+J11) -> 0.037452045
A12: AT | B12: 2012 | C12: 1060802488 | D12: 781143340 | E12: 789811574 | F12: 258039203 | G12: 768345370 | H12: 969213681 | I12: 89720947755 | J12: 42441771623 | K12: =SUM(C12:H12)/(I12+J12) -> 0.035012564
A13: AT | B13: 2013 | C13: 1030942848 | D13: 841023054 | E13: 1149708436 | F13: 312350804 | G13: 760434903 | H13: 821562420 | I13: 91877747537 | J13: 43222225158 | K13: =SUM(C13:H13)/(I13+J13) -> 0.036388034
... A241: PT | B241: 2025 | C241: 718725956 | D241: 345747963 | E241: 147241712 | F241: 65855892 | G241: 137576409 | H241: 81760398 | I241: 56949272888 | J241: 22018254621 | K241: =SUM(C241:H241)/(I241+J241) -> 0.018955998

Sheet wui
A1: quarter | B1: wui_global
A2: 1990Q1 | B2: 12496.47
A3: 1990Q2 | B3: 8769.965
A4: 1990Q3 | B4: 16198.83
A5: 1990Q4 | B5: 11872.27
A6: 1991Q1 | B6: 8223.55
A7: 1991Q2 | B7: 10483.81
A8: 1991Q3 | B8: 6208.322
A9: 1991Q4 | B9: 7314.133
A10: 1992Q1 | B10: 12616.9
A11: 1992Q2 | B11: 7358.835
A12: 1992Q3 | B12: 6777.611
A13: 1992Q4 | B13: 13982.37
... A147: 2026Q2 | B147: 77922.84

Sheet gpr
A1: quarter | B1: gpr_global
A2: 1900Q1
A3: 1900Q2
A4: 1900Q3
A5: 1900Q4
A6: 1901Q1
A7: 1901Q2
A8: 1901Q3
A9: 1901Q4
A10: 1902Q1
A11: 1902Q2
A12: 1902Q3
A13: 1902Q4
... A341: 1984Q4
A342: 1985Q1 | B342: 114.68452
A343: 1985Q2 | B343: 113.32489
A344: 1985Q3 | B344: 106.37467
A345: 1985Q4 | B345: 99.087087
A346: 1986Q1 | B346: 110.92915
A347: 1986Q2 | B347: 120.66578
A348: 1986Q3 | B348: 105.05187
A349: 1986Q4 | B349: 98.77301
A350: 1987Q1 | B350: 95.744629
A351: 1987Q2 | B351: 102.0758
A352: 1987Q3 | B352: 106.66916
A353: 1987Q4 | B353: 102.35615
... A508: 2026Q3 | B508: 146.56607

Sheet epu
A1: quarter | B1: epu_global
A2: 1997Q1 | B2: 74.770187
A3: 1997Q2 | B3: 77.463074
A4: 1997Q3 | B4: 65.491694
A5: 1997Q4 | B5: 95.972339
A6: 1998Q1 | B6: 91.132628
A7: 1998Q2 | B7: 83.346614
A8: 1998Q3 | B8: 122.67404
A9: 1998Q4 | B9: 105.82335
A10: 1999Q1 | B10: 81.105263
A11: 1999Q2 | B11: 69.228681
A12: 1999Q3 | B12: 69.89554
A13: 1999Q4 | B13: 66.469898
... A120: 2026Q3 | B120: 241.69049

Sheet tpu
A1: quarter | B1: tpu_global
A2: 1960Q1 | B2: 14.9493
A3: 1960Q2 | B3: 16.928593
A4: 1960Q3 | B4: 15.502807
A5: 1960Q4 | B5: 16.523557
A6: 1961Q1 | B6: 18.406929
A7: 1961Q2 | B7: 14.928116
A8: 1961Q3 | B8: 17.296939
A9: 1961Q4 | B9: 31.278054
A10: 1962Q1 | B10: 38.76535
A11: 1962Q2 | B11: 31.400813
A12: 1962Q3 | B12: 31.582582
A13: 1962Q4 | B13: 23.523095
... A267: 2026Q2 | B267: 194.8809

Sheet gscpi
A1: quarter | B1: gscpi_global
A2: 1998Q1 | B2: -0.44214436
A3: 1998Q2 | B3: -0.4882678
A4: 1998Q3 | B4: -0.9231494
A5: 1998Q4 | B5: -0.77067888
A6: 1999Q1 | B6: -0.25416227
A7: 1999Q2 | B7: -0.42869599
A8: 1999Q3 | B8: -0.57725997
A9: 1999Q4 | B9: -0.27240404
A10: 2000Q1 | B10: -0.4797868
A11: 2000Q2 | B11: 0.10957476
A12: 2000Q3 | B12: 0.019289442
A13: 2000Q4 | B13: -0.64864284
... A116: 2026Q3 | B116: 1.1370275

Sheet com
A1: quarter | B1: commodity_price_index
A2: 1992Q1 | B2: 47.928102
A3: 1992Q2 | B3: 49.667459
A4: 1992Q3 | B4: 51.140282
A5: 1992Q4 | B5: 49.160205
A6: 1993Q1 | B6: 48.499151
A7: 1993Q2 | B7: 49.773052
A8: 1993Q3 | B8: 48.356852
A9: 1993Q4 | B9: 46.995259
A10: 1994Q1 | B10: 47.720813
A11: 1994Q2 | B11: 49.815667
A12: 1994Q3 | B12: 51.634008
A13: 1994Q4 | B13: 52.456731
... A139: 2026Q2 | B139: 207.79466

Sheet trade_openness
A1: country | B1: year | C1: trade_openness
A2: AT | B2: 2000 | C2: 85.842608
A3: AT | B3: 2001 | C3: 87.996257
A4: AT | B4: 2002 | C4: 87.584494
A5: AT | B5: 2003 | C5: 86.882226
A6: AT | B6: 2004 | C6: 91.47422
A7: AT | B7: 2005 | C7: 94.674755
A8: AT | B8: 2006 | C8: 98.785725
A9: AT | B9: 2007 | C9: 101.36496
A10: AT | B10: 2008 | C10: 102.7437
A11: AT | B11: 2009 | C11: 87.600493
A12: AT | B12: 2010 | C12: 99.644883
A13: AT | B13: 2011 | C13: 105.7751
... A261: PT | B261: 2025 | C261: 86.398877

Sheet population_growth
A1: country | B1: year | C1: population_growth
A2: AT | B2: 2000 | C2: 0.24046665
A3: AT | B3: 2001 | C3: 0.38279939
A4: AT | B4: 2002 | C4: 0.49198046
A5: AT | B5: 2003 | C5: 0.48713389
A6: AT | B6: 2004 | C6: 0.62041313
A7: AT | B7: 2005 | C7: 0.68126725
A8: AT | B8: 2006 | C8: 0.49479778
A9: AT | B9: 2007 | C9: 0.32414654
A10: AT | B10: 2008 | C10: 0.31304144
A11: AT | B11: 2009 | C11: 0.26195319
A12: AT | B12: 2010 | C12: 0.2403943
A13: AT | B13: 2011 | C13: 0.33708084
... A261: PT | B261: 2025 | C261: 1.0250536

Sheet productivity_growth
A1: country | B1: year | C1: productivity_growth
A2: AT | B2: 2001 | C2: 1.3508369
A3: AT | B3: 2002 | C3: 1.7177641
A4: AT | B4: 2003 | C4: 0.96633751
A5: AT | B5: 2004 | C5: 1.769571
A6: AT | B6: 2005 | C6: 2.4975553
A7: AT | B7: 2006 | C7: 2.4475422
A8: AT | B8: 2007 | C8: 2.4949208
A9: AT | B9: 2008 | C9: -0.035978075
A10: AT | B10: 2009 | C10: -0.36049448
A11: AT | B11: 2010 | C11: 1.4405277
A12: AT | B12: 2011 | C12: 0.97418421
A13: AT | B13: 2012 | C13: 1.0581891
... A251: PT | B251: 2025 | C251: 0.22522423

Sheet gdp_per_capita
A1: country | B1: year | C1: gdp_per_capita
A2: AT | B2: 2000 | C2: 31510
A3: AT | B3: 2001 | C3: 31800
A4: AT | B4: 2002 | C4: 32120
A5: AT | B5: 2003 | C5: 32340
A6: AT | B6: 2004 | C6: 32960
A7: AT | B7: 2005 | C7: 33500
A8: AT | B8: 2006 | C8: 34410
A9: AT | B9: 2007 | C9: 35600
A10: AT | B10: 2008 | C10: 36000
A11: AT | B11: 2009 | C11: 34630
A12: AT | B12: 2010 | C12: 35170
A13: AT | B13: 2011 | C13: 36080
... A261: PT | B261: 2025 | C261: 19830

Sheet infl
A1: country | B1: quarter | C1: hicp_index
A2: AT | B2: 2000Q1 | C2: 74.683333
A3: AT | B3: 2000Q2 | C3: 74.83
A4: AT | B4: 2000Q3 | C4: 74.923333
A5: AT | B5: 2000Q4 | C5: 75.64
A6: AT | B6: 2001Q1 | C6: 76.166667
A7: AT | B7: 2001Q2 | C7: 76.843333
A8: AT | B8: 2001Q3 | C8: 76.82
A9: AT | B9: 2001Q4 | C9: 77.146667
A10: AT | B10: 2002Q1 | C10: 77.52
A11: AT | B11: 2002Q2 | C11: 78.07
A12: AT | B12: 2002Q3 | C12: 78.12
A13: AT | B13: 2002Q4 | C13: 78.43
... A1041: PT | B1041: 2025Q4 | C1041: 125.55

Sheet support
A1: country | B1: year | C1: state_aid_m_eur | D1: gdp_m_eur | E1: support_share
A2: AT | B2: 2000 | C2: 465.16934 | D2: 212406.8 | E2: 0.0021899927
A3: AT | B3: 2001 | C3: 651.73849 | D3: 219373.3 | E3: 0.0029709107
A4: AT | B4: 2002 | C4: 789.4794 | D4: 225087.9 | E4: 0.0035074271
A5: AT | B5: 2003 | C5: 1122.8563 | D5: 230541.9 | E5: 0.0048705086
A6: AT | B6: 2004 | C6: 1126.6842 | D6: 240541.7 | E6: 0.0046839454
A7: AT | B7: 2005 | C7: 1129.5243 | D7: 252354.9 | E7: 0.0044759357
A8: AT | B8: 2006 | C8: 1251.8298 | D8: 265933.7 | E8: 0.0047073004
A9: AT | B9: 2007 | C9: 1166.4323 | D9: 282208.2 | E9: 0.0041332332
A10: AT | B10: 2008 | C10: 1489.1082 | D10: 291846.2 | E10: 0.0051023731
A11: AT | B11: 2009 | C11: 1725.3748 | D11: 286274.1 | E11: 0.0060270028
A12: AT | B12: 2010 | C12: 1920.9957 | D12: 294050.6 | E12: 0.0065328746
A13: AT | B13: 2011 | C13: 1685.234 | D13: 308167 | E13: 0.0054685739
... A251: PT | B251: 2024 | C251: 1079.4098 | D251: 291152.8 | E251: 0.0037073653
