Workbook

Sheet gdp
A1: country | B1: quarter | C1: gdp_level
A2: AT | B2: 2000Q1 | C2: 62065.3
A3: AT | B3: 2000Q2 | C3: 62777
A4: AT | B4: 2000Q3 | C4: 63651.3
A5: AT | B5: 2000Q4 | C5: 64086.8
A6: AT | B6: 2001Q1 | C6: 63895.5
A7: AT | B7: 2001Q2 | C7: 63713.8
A8: AT | B8: 2001Q3 | C8: 63968.3
A9: AT | B9: 2001Q4 | C9: 64117.7
A10: AT | B10: 2002Q1 | C10: 64830.9
A11: AT | B11: 2002Q2 | C11: 64997.2
A12: AT | B12: 2002Q3 | C12: 64992.2
A13: AT | B13: 2002Q4 | C13: 64665
... A1061: PT | B1061: 2026Q2 | C1061: 54437.6

Sheet ict_inv
A1: country | B1: year | C1: N1132G | D1: N1173G | E1: N112G_secJ | F1: N117G_secJ | G1: N1173G_secJ | H1: N11G | I1: ict_share
A2: AT | B2: 2000 | C2: 3774.2 | D2: 3129.8 | E2: 421.5 | F2: 613.7 | G2: 424.8 | H2: 54601.4 | I2: =(C2+D2+E2+F2-G2)/H2 -> 0.13762284
A3: AT | B3: 2001 | C3: 3812.6 | D3: 3604.5 | E3: 268.9 | F3: 708.4 | G3: 486.4 | H3: 54685.2 | I3: =(C3+D3+E3+F3-G3)/H3 -> 0.14460951
A4: AT | B4: 2002 | C4: 3337.6 | D4: 3948.2 | E4: 211.5 | F4: 782 | G4: 542.9 | H4: 53172.7 | I4: =(C4+D4+E4+F4-G4)/H4 -> 0.14549571
A5: AT | B5: 2003 | C5: 3288.4 | D5: 3863.3 | E5: 68.8 | F5: 772.3 | G5: 520.3 | H5: 55777.6 | I5: =(C5+D5+E5+F5-G5)/H5 -> 0.13396955
A6: AT | B6: 2004 | C6: 3354.3 | D6: 3960.8 | E6: 80.6 | F6: 814.2 | G6: 533.8 | H6: 57172.6 | I6: =(C6+D6+E6+F6-G6)/H6 -> 0.13426187
A7: AT | B7: 2005 | C7: 3359.7 | D7: 3807.6 | E7: 81 | F7: 811.9 | G7: 516.4 | H7: 58633.6 | I7: =(C7+D7+E7+F7-G7)/H7 -> 0.12866002
A8: AT | B8: 2006 | C8: 3225 | D8: 4126.9 | E8: 62.9 | F8: 926.1 | G8: 585.6 | H8: 60714.5 | I8: =(C8+D8+E8+F8-G8)/H8 -> 0.1277339
A9: AT | B9: 2007 | C9: 3497.5 | D9: 4185.3 | E9: 159.1 | F9: 1030.9 | G9: 615.7 | H9: 65301.3 | I9: =(C9+D9+E9+F9-G9)/H9 -> 0.12644618
A10: AT | B10: 2008 | C10: 3839.2 | D10: 4491.8 | E10: 124.7 | F10: 1059.7 | G10: 656.9 | H10: 68682.5 | I10: =(C10+D10+E10+F10-G10)/H10 -> 0.12897754
A11: AT | B11: 2009 | C11: 3334.9 | D11: 4610.1 | E11: 119.8 | F11: 1418.3 | G11: 1062.9 | H11: 64880.3 | I11: =(C11+D11+E11+F11-G11)/H11 -> 0.12978053
A12: AT | B12: 2010 | C12: 3694.8 | D12: 4787.2 | E12: 49.8 | F12: 1441.8 | G12: 1005.3 | H12: 64282.9 | I12: =(C12+D12+E12+F12-G12)/H12 -> 0.139513
A13: AT | B13: 2011 | C13: 3792.1 | D13: 5830.1 | E13: 74.7 | F13: 1586.9 | G13: 1017.2 | H13: 69976.6 | I13: =(C13+D13+E13+F13-G13)/H13 -> 0.14671476
... A152: FR | B152: 2024 | C152: 12314 | D152: 93190.9 | E152: 4843.3 | F152: 28213.3 | G152: 20022 | H152: 645205.8 | I152: =(C152+D152+E152+F152-G152)/H152 -> 0.18372355
A153: IE | B153: 2000 | C153: 1204.4 | D153: 460.3 | E153: 217.7 | F153: 470.5 | H153: 25759 | I153: =(C153+D153+E153+F153-G153)/H153 -> 0.091342832
A154: IE | B154: 2001 | C154: 1088.8 | D154: 647.9 | E154: 254.9 | F154: 936.4 | H154: 29223.7 | I154: =(C154+D154+E154+F154-G154)/H154 -> 0.10019265
A155: IE | B155: 2002 | C155: 915.5 | D155: 571.6 | E155: 290.2 | F155: 1263 | H155: 32086.1 | I155: =(C155+D155+E155+F155-G155)/H155 -> 0.094754426
A156: IE | B156: 2003 | C156: 820.1 | D156: 607.9 | E156: 294.8 | F156: 1227.9 | H156: 36264.8 | I156: =(C156+D156+E156+F156-G156)/H156 -> 0.081365401
A157: IE | B157: 2004 | C157: 888.6 | D157: 676.9 | E157: 307.6 | F157: 1554.8 | H157: 42112.5 | I157: =(C157+D157+E157+F157-G157)/H157 -> 0.081398635
A158: IE | B158: 2005 | C158: 795.1 | D158: 703.6 | E158: 277.4 | F158: 1436.7 | H158: 50800.7 | I158: =(C158+D158+E158+F158-G158)/H158 -> 0.063243223
A159: IE | B159: 2006 | C159: 1072.6 | D159: 776.6 | E159: 343 | F159: 1672.1 | H159: 57299.4 | I159: =(C159+D159+E159+F159-G159)/H159 -> 0.067440497
A160: IE | B160: 2007 | C160: 1335.7 | D160: 919.9 | E160: 379.3 | F160: 1587.9 | H160: 56572.9 | I160: =(C160+D160+E160+F160-G160)/H160 -> 0.074643513
A161: IE | B161: 2008 | C161: 1136.5 | D161: 920.5 | E161: 448.1 | F161: 1927.2 | H161: 46525.1 | I161: =(C161+D161+E161+F161-G161)/H161 -> 0.095266856
A162: IE | B162: 2009 | C162: 1166.7 | D162: 910 | E162: 217.7 | F162: 2313.5 | H162: 35875.7 | I162: =(C162+D162+E162+F162-G162)/H162 -> 0.1284407
A163: IE | B163: 2010 | C163: 1156.9 | D163: 1037.5 | E163: 344.1 | F163: 2505.3 | H163: 29422.5 | I163: =(C163+D163+E163+F163-G163)/H163 -> 0.17142663
A164: IE | B164: 2011 | C164: 1986 | D164: 1087.2 | E164: 324.2 | F164: 2708.2 | H164: 28677.5 | I164: =(C164+D164+E164+F164-G164)/H164 -> 0.21290559
... A177: IE | B177: 2024 | C177: 3132 | D177: 6961.8 | E177: 859.8 | F177: -1579.6 | H177: 97633.6 | I177: =(C177+D177+E177+F177-G177)/H177 -> 0.096012029
A178: IT | B178: 2000 | C178: 13266.4 | D178: 17549.5 | E178: 1574.4 | F178: 6378.8 | G178: 4518.1 | H178: 264206.4 | I178: =(C178+D178+E178+F178-G178)/H178 -> 0.12963728
A179: IT | B179: 2001 | C179: 12798.5 | D179: 18903 | E179: 2331.2 | F179: 6522.9 | G179: 4728.8 | H179: 277322 | I179: =(C179+D179+E179+F179-G179)/H179 -> 0.12918845
A180: IT | B180: 2002 | C180: 12997.1 | D180: 19853.3 | E180: 1600.3 | F180: 6729.4 | G180: 4861.7 | H180: 295667.7 | I180: =(C180+D180+E180+F180-G180)/H180 -> 0.1228352
A181: IT | B181: 2003 | C181: 12188.5 | D181: 19090.9 | E181: 1785.2 | F181: 7396.5 | G181: 5403.5 | H181: 297848.6 | I181: =(C181+D181+E181+F181-G181)/H181 -> 0.11770275
A182: IT | B182: 2004 | C182: 13790.2 | D182: 18144.7 | E182: 1939.1 | F182: 6459.1 | G182: 4395 | H182: 311288.4 | I182: =(C182+D182+E182+F182-G182)/H182 -> 0.11544953
A183: IT | B183: 2005 | C183: 14574.4 | D183: 18591.8 | E183: 2421.4 | F183: 6782.8 | G183: 4694.2 | H183: 324900.7 | I183: =(C183+D183+E183+F183-G183)/H183 -> 0.1159622
A184: IT | B184: 2006 | C184: 13499.2 | D184: 19057.2 | E184: 2373.7 | F184: 6760.6 | G184: 4632.4 | H184: 341988.4 | I184: =(C184+D184+E184+F184-G184)/H184 -> 0.10836128
A185: IT | B185: 2007 | C185: 13967.5 | D185: 20015 | E185: 2278.8 | F185: 7594.4 | G185: 5222.3 | H185: 356687.6 | I185: =(C185+D185+E185+F185-G185)/H185 -> 0.10831159
A186: IT | B186: 2008 | C186: 13209.2 | D186: 19877.7 | E186: 1909.9 | F186: 7504.2 | G186: 4971.9 | H186: 354419.4 | I186: =(C186+D186+E186+F186-G186)/H186 -> 0.10588896
A187: IT | B187: 2009 | C187: 11088.7 | D187: 19211.2 | E187: 1515.2 | F187: 7071.5 | G187: 4417.3 | H187: 321826.5 | I187: =(C187+D187+E187+F187-G187)/H187 -> 0.10710523
A188: IT | B188: 2010 | C188: 13344.3 | D188: 19721.9 | E188: 1988.3 | F188: 7568.8 | G188: 4839.5 | H188: 327450.4 | I188: =(C188+D188+E188+F188-G188)/H188 -> 0.11538786
A189: IT | B189: 2011 | C189: 13490.8 | D189: 19015.5 | E189: 2136.4 | F189: 7303.5 | G189: 4703.5 | H189: 329961.7 | I189: =(C189+D189+E189+F189-G189)/H189 -> 0.11286977
... A228: NL | B228: 2024 | C228: 8359 | D228: 24651 | E228: 2491 | F228: 4258 | G228: 2285 | H228: 222797 | I228: =(C228+D228+E228+F228-G228)/H228 -> 0.16819796
...

Sheet ai_patent
A1: country | B1: year | C1: ai_patents
A2: AT | B2: 2015 | C2: 3
A3: AT | B3: 2016 | C3: 10
A4: AT | B4: 2017 | C4: 11
A5: AT | B5: 2018 | C5: 12
A6: AT | B6: 2019 | C6: 6
A7: AT | B7: 2020 | C7: 15
A8: AT | B8: 2021 | C8: 15
A9: AT | B9: 2022 | C9: 9
A10: AT | B10: 2023 | C10: 1
A11: AT | B11: 2024 | C11: 0
A12: AT | B12: 2025 | C12: 0
A13: BE | B13: 2015 | C13: 0
... A111: PT | B111: 2025 | C111: 0

Sheet ai_inv
A1: country | B1: year | C1: ai_investment | D1: share
A2: AT | B2: 2015 | C2: 3 | D2: =(C2/gdp!C65)*1000 -> 0.038424346
A3: AT | B3: 2016 | C3: 21 | D3: =(C3/gdp!C69)*1000 -> 0.26303066
A4: AT | B4: 2017 | C4: 24 | D4: =(C4/gdp!C73)*1000 -> 0.29345091
A5: AT | B5: 2018 | C5: 39 | D5: =(C5/gdp!C77)*1000 -> 0.4640824
A6: AT | B6: 2019 | C6: 43 | D6: =(C6/gdp!C81)*1000 -> 0.51159537
A7: AT | B7: 2020 | C7: 47 | D7: =(C7/gdp!C85)*1000 -> 0.5890588
A8: AT | B8: 2021 | C8: 67 | D8: =(C8/gdp!C89)*1000 -> 0.78389345
A9: AT | B9: 2022 | C9: 68 | D9: =(C9/gdp!C93)*1000 -> 0.77085445
A10: AT | B10: 2023 | C10: 149 | D10: =(C10/gdp!C97)*1000 -> 1.7280872
A11: AT | B11: 2024 | C11: 133 | D11: =(C11/gdp!C101)*1000 -> 1.5374709
A12: AT | B12: 2025 | C12: 75 | D12: =(C12/gdp!C105)*1000 -> 0.85797436
A13: BE | B13: 2015 | C13: 38 | D13: =(C13/gdp!C171)*1000 -> 0.39371506
A14: BE | B14: 2016 | C14: 12 | D14: =(C14/gdp!C175)*1000 -> 0.12278363
A15: BE | B15: 2017 | C15: 54 | D15: =(C15/gdp!C179)*1000 -> 0.54390414
A16: BE | B16: 2018 | C16: 26 | D16: =(C16/gdp!C183)*1000 -> 0.25601336
A17: BE | B17: 2019 | C17: 30 | D17: =(C17/gdp!C187)*1000 -> 0.28857836
A18: BE | B18: 2020 | C18: 70 | D18: =(C18/gdp!C191)*1000 -> 0.69919523
A19: BE | B19: 2021 | C19: 65 | D19: =(C19/gdp!C195)*1000 -> 0.61145107
A20: BE | B20: 2022 | C20: 79 | D20: =(C20/gdp!C199)*1000 -> 0.72263059
A21: BE | B21: 2023 | C21: 61 | D21: =(C21/gdp!C203)*1000 -> 0.55195078
A22: BE | B22: 2024 | C22: 97 | D22: =(C22/gdp!C207)*1000 -> 0.86948182
A23: BE | B23: 2025 | C23: 121 | D23: =(C23/gdp!C211)*1000 -> 1.074587
A24: DE | B24: 2015 | C24: 106 | D24: =(C24/gdp!C277)*1000 -> 0.14767369
A25: DE | B25: 2016 | C25: 168 | D25: =(C25/gdp!C281)*1000 -> 0.22940969
A26: DE | B26: 2017 | C26: 245 | D26: =(C26/gdp!C285)*1000 -> 0.32172079
A27: DE | B27: 2018 | C27: 265 | D27: =(C27/gdp!C289)*1000 -> 0.34755507
A28: DE | B28: 2019 | C28: 389 | D28: =(C28/gdp!C293)*1000 -> 0.50617356
A29: DE | B29: 2020 | C29: 404 | D29: =(C29/gdp!C297)*1000 -> 0.53632279
A30: DE | B30: 2021 | C30: 710 | D30: =(C30/gdp!C301)*1000 -> 0.92018115
A31: DE | B31: 2022 | C31: 886 | D31: =(C31/gdp!C305)*1000 -> 1.1381739
A32: DE | B32: 2023 | C32: 846 | D32: =(C32/gdp!C309)*1000 -> 1.0970433
A33: DE | B33: 2024 | C33: 791 | D33: =(C33/gdp!C313)*1000 -> 1.0215985
A34: DE | B34: 2025 | C34: 818 | D34: =(C34/gdp!C317)*1000 -> 1.0529127
A35: ES | B35: 2015 | C35: 67 | D35: =(C35/gdp!C383)*1000 -> 0.24412541
A36: ES | B36: 2016 | C36: 91 | D36: =(C36/gdp!C387)*1000 -> 0.32378661
A37: ES | B37: 2017 | C37: 89 | D37: =(C37/gdp!C391)*1000 -> 0.3073647
A38: ES | B38: 2018 | C38: 109 | D38: =(C38/gdp!C395)*1000 -> 0.36818229
A39: ES | B39: 2019 | C39: 138 | D39: =(C39/gdp!C399)*1000 -> 0.45846719
A40: ES | B40: 2020 | C40: 161 | D40: =(C40/gdp!C403)*1000 -> 0.58774375
...

Sheet index_nat
A1: country | B1: ticker | C1: quarter | D1: close | E1: log_ret
A2: NL | B2: ^AEX | C2: 2000Q1 | D2: 662.28998
A3: NL | B3: ^AEX | C3: 2000Q2 | D3: 672.14001 | E3: 0.014763181
A4: NL | B4: ^AEX | C4: 2000Q3 | D4: 661.52002 | E4: -0.015926427
A5: NL | B5: ^AEX | C5: 2000Q4 | D5: 637.59998 | E5: -0.036829158
A6: NL | B6: ^AEX | C6: 2001Q1 | D6: 558.35999 | E6: -0.1327072
A7: NL | B7: ^AEX | C7: 2001Q2 | D7: 573.5 | E7: 0.026754047
A8: NL | B8: ^AEX | C8: 2001Q3 | D8: 453.87 | E8: -0.23394713
A9: NL | B9: ^AEX | C9: 2001Q4 | D9: 506.78 | E9: 0.11026618
A10: NL | B10: ^AEX | C10: 2002Q1 | D10: 531.21002 | E10: 0.047080483
A11: NL | B11: ^AEX | C11: 2002Q2 | D11: 439.66 | E11: -0.18915576
A12: NL | B12: ^AEX | C12: 2002Q3 | D12: 296.35999 | E12: -0.39442683
A13: NL | B13: ^AEX | C13: 2002Q4 | D13: 322.73001 | E13: 0.085241212
A14: NL | B14: ^AEX | C14: 2003Q1 | D14: 248.53999 | E14: -0.26121232
... A107: NL | B107: ^AEX | C107: 2026Q2 | D107: 1065.34 | E107: 0.10432433
A108: DE | B108: ^GDAXI | C108: 2000Q1 | D108: 7599.3901
A109: DE | B109: ^GDAXI | C109: 2000Q2 | D109: 6898.21 | E109: -0.096806047
A110: DE | B110: ^GDAXI | C110: 2000Q3 | D110: 6798.1201 | E110: -0.014615831
A111: DE | B111: ^GDAXI | C111: 2000Q4 | D111: 6433.6099 | E111: -0.05511033
A112: DE | B112: ^GDAXI | C112: 2001Q1 | D112: 5829.9502 | E112: -0.098527333
A113: DE | B113: ^GDAXI | C113: 2001Q2 | D113: 6058.3799 | E113: 0.038433961
A114: DE | B114: ^GDAXI | C114: 2001Q3 | D114: 4308.1499 | E114: -0.34093386
A115: DE | B115: ^GDAXI | C115: 2001Q4 | D115: 5160.1001 | E115: 0.18044742
A116: DE | B116: ^GDAXI | C116: 2002Q1 | D116: 5397.29 | E116: 0.044941005
A117: DE | B117: ^GDAXI | C117: 2002Q2 | D117: 4382.5601 | E117: -0.20826394
A118: DE | B118: ^GDAXI | C118: 2002Q3 | D118: 2769.03 | E118: -0.45913595
A119: DE | B119: ^GDAXI | C119: 2002Q4 | D119: 2892.6299 | E119: 0.043668993
A120: DE | B120: ^GDAXI | C120: 2003Q1 | D120: 2423.8701 | E120: -0.1768006
... A213: DE | B213: ^GDAXI | C213: 2026Q2 | D213: 24626.891 | E213: 0.08235376
A214: FR | B214: ^FCHI | C214: 2000Q1 | D214: 6286.0498
A215: FR | B215: ^FCHI | C215: 2000Q2 | D215: 6446.54 | E215: 0.025210697
A216: FR | B216: ^FCHI | C216: 2000Q3 | D216: 6266.6299 | E216: -0.028304847
A217: FR | B217: ^FCHI | C217: 2000Q4 | D217: 5926.4199 | E217: -0.055818404
A218: FR | B218: ^FCHI | C218: 2001Q1 | D218: 5180.4502 | E218: -0.13452834
A219: FR | B219: ^FCHI | C219: 2001Q2 | D219: 5225.3301 | E219: 0.0086260059
A220: FR | B220: ^FCHI | C220: 2001Q3 | D220: 4079.02 | E220: -0.2476612
A221: FR | B221: ^FCHI | C221: 2001Q4 | D221: 4624.5801 | E221: 0.1255288
A222: FR | B222: ^FCHI | C222: 2002Q1 | D222: 4688.02 | E222: 0.01362475
A223: FR | B223: ^FCHI | C223: 2002Q2 | D223: 3897.99 | E223: -0.18454929
A224: FR | B224: ^FCHI | C224: 2002Q3 | D224: 2777.45 | E224: -0.33892781
...

Sheet index_sox
A1: ticker | B1: quarter | C1: close | D1: log_ret
A2: ^SOX | B2: 2000Q1 | C2: 1181.3184
A3: ^SOX | B3: 2000Q2 | C3: 1139.9784 | D3: -0.035621759
A4: ^SOX | B4: 2000Q3 | C4: 851.15814 | D4: -0.29216665
A5: ^SOX | B5: 2000Q4 | C5: 576.33112 | D5: -0.38991559
A6: ^SOX | B6: 2001Q1 | C6: 544.77637 | D6: -0.056306974
A7: ^SOX | B7: 2001Q2 | C7: 623.78821 | D7: 0.13543553
A8: ^SOX | B8: 2001Q3 | C8: 373.51929 | D8: -0.51284126
A9: ^SOX | B9: 2001Q4 | C9: 521.90741 | D9: 0.33452055
A10: ^SOX | B10: 2002Q1 | C10: 594.95209 | D10: 0.13099068
A11: ^SOX | B11: 2002Q2 | C11: 387.39255 | D11: -0.42904236
A12: ^SOX | B12: 2002Q3 | C12: 238.12479 | D12: -0.48664367
A13: ^SOX | B13: 2002Q4 | C13: 289.1001 | D13: 0.19397814
A14: ^SOX | B14: 2003Q1 | C14: 296.12671 | D14: 0.024014447
... A107: ^SOX | B107: 2026Q2 | C107: 13709.66 | D107: 0.59150627

Sheet index_msci
A1: ticker | B1: quarter | C1: close | D1: log_ret
A2: ^990100-USD-STRD | B2: 2000Q1 | C2: 1419.5
A3: ^990100-USD-STRD | B3: 2000Q2 | C3: 1366.2 | D3: -0.038271569
A4: ^990100-USD-STRD | B4: 2000Q3 | C4: 1312.4 | D4: -0.040175587
A5: ^990100-USD-STRD | B5: 2000Q4 | C5: 1228.5 | D5: -0.066063628
A6: ^990100-USD-STRD | B6: 2001Q1 | C6: 1055.2 | D6: -0.15206364
A7: ^990100-USD-STRD | B7: 2001Q2 | C7: 1086.6 | D7: 0.029323257
A8: ^990100-USD-STRD | B8: 2001Q3 | C8: 925.70001 | D8: -0.16025859
A9: ^990100-USD-STRD | B9: 2001Q4 | C9: 1003.1 | D9: 0.080300238
A10: ^990100-USD-STRD | B10: 2002Q1 | C10: 1003.6 | D10: 0.00049833061
A11: ^990100-USD-STRD | B11: 2002Q2 | C11: 909.29999 | D11: -0.098673731
A12: ^990100-USD-STRD | B12: 2002Q3 | C12: 737.79999 | D12: -0.20900229
A13: ^990100-USD-STRD | B13: 2002Q4 | C13: 792.40002 | D13: 0.071393577
A14: ^990100-USD-STRD | B14: 2003Q1 | C14: 766.59998 | D14: -0.033101225
... A107: ^990100-USD-STRD | B107: 2026Q2 | C107: 4790.5 | D107: 0.11776482

Sheet index_stoxx600
A1: ticker | B1: quarter | C1: close | D1: log_ret | E1: source
A2: ^STOXX (proxied via ^GDAXI) | B2: 2000Q1 | C2: 451.64349 | E2: DAX_proxy
A3: ^STOXX (proxied via ^GDAXI) | B3: 2000Q2 | C3: 409.97127 | D3: -0.096806047 | E3: DAX_proxy
A4: ^STOXX (proxied via ^GDAXI) | B4: 2000Q3 | C4: 404.02278 | D4: -0.014615831 | E4: DAX_proxy
A5: ^STOXX (proxied via ^GDAXI) | B5: 2000Q4 | C5: 382.35937 | D5: -0.05511033 | E5: DAX_proxy
A6: ^STOXX (proxied via ^GDAXI) | B6: 2001Q1 | C6: 346.48294 | D6: -0.098527333 | E6: DAX_proxy
A7: ^STOXX (proxied via ^GDAXI) | B7: 2001Q2 | C7: 360.05887 | D7: 0.038433961 | E7: DAX_proxy
A8: ^STOXX (proxied via ^GDAXI) | B8: 2001Q3 | C8: 256.04 | D8: -0.34093386 | E8: DAX_proxy
A9: ^STOXX (proxied via ^GDAXI) | B9: 2001Q4 | C9: 306.67272 | D9: 0.18044742 | E9: DAX_proxy
A10: ^STOXX (proxied via ^GDAXI) | B10: 2002Q1 | C10: 320.76928 | D10: 0.044941005 | E10: DAX_proxy
A11: ^STOXX (proxied via ^GDAXI) | B11: 2002Q2 | C11: 260.46231 | D11: -0.20826394 | E11: DAX_proxy
A12: ^STOXX (proxied via ^GDAXI) | B12: 2002Q3 | C12: 164.56773 | D12: -0.45913595 | E12: DAX_proxy
A13: ^STOXX (proxied via ^GDAXI) | B13: 2002Q4 | C13: 171.91346 | D13: 0.043668993 | E13: DAX_proxy
A14: ^STOXX (proxied via ^GDAXI) | B14: 2003Q1 | C14: 144.05434 | D14: -0.1768006 | E14: DAX_proxy
... A18: ^STOXX (proxied via ^GDAXI) | B18: 2004Q1 | C18: 229.20963 | D18: -0.027734302 | E18: DAX_proxy
A19: ^STOXX | B19: 2004Q2 | C19: 240.86 | E19: STOXX600
A20: ^STOXX | B20: 2004Q3 | C20: 237.74001 | D20: -0.013038192 | E20: STOXX600
A21: ^STOXX | B21: 2004Q4 | C21: 251.02 | D21: 0.054354972 | E21: STOXX600
A22: ^STOXX | B22: 2005Q1 | C22: 262.19 | D22: 0.043536807 | E22: STOXX600
A23: ^STOXX | B23: 2005Q2 | C23: 275.92001 | D23: 0.051041576 | E23: STOXX600
A24: ^STOXX | B24: 2005Q3 | C24: 297.39999 | D24: 0.074966996 | E24: STOXX600
A25: ^STOXX | B25: 2005Q4 | C25: 310.03 | D25: 0.04159105 | E25: STOXX600
A26: ^STOXX | B26: 2006Q1 | C26: 334.44 | D26: 0.075788436 | E26: STOXX600
A27: ^STOXX | B27: 2006Q2 | C27: 320.66 | D27: -0.042076115 | E27: STOXX600
A28: ^STOXX | B28: 2006Q3 | C28: 341.42999 | D28: 0.062761275 | E28: STOXX600
A29: ^STOXX | B29: 2006Q4 | C29: 365.26001 | D29: 0.067466797 | E29: STOXX600
A30: ^STOXX | B30: 2007Q1 | C30: 374.22 | D30: 0.024234408 | E30: STOXX600
A31: ^STOXX | B31: 2007Q2 | C31: 393.70999 | D31: 0.050770713 | E31: STOXX600
... A107: ^STOXX | B107: 2026Q2 | C107: 636.10999 | D107: 0.086944161 | E107: STOXX600

Sheet hs_export
A1: country | B1: year | C1: CPA 2.2 261 extra | D1: CPA 2.2 261 intra | E1: CPA 2.2 262 extra | F1: CPA 2.2 262 intra | G1: CPA 2.2 2899 extra | H1: CPA 2.2 2899 intra | K1: total_export | L1: share
A2: AT | B2: 2002 | C2: 970441011 | D2: 1352970368 | E2: 594216714 | F2: 1050392413 | G2: 452688130 | H2: 272694726 | K2: 83198982398 | L2: =SUM(C2:H2)/K2 -> 0.056411788
A3: AT | B3: 2003 | C3: 849582646 | D3: 1314284036 | E3: 563719201 | F3: 1057292411 | G3: 445117617 | H3: 289045216 | K3: 85878805465 | L3: =SUM(C3:H3)/K3 -> 0.052621146
A4: AT | B4: 2004 | C4: 671840601 | D4: 1504953676 | E4: 746097643 | F4: 1381763681 | G4: 524165921 | H4: 390540891 | K4: 95164850432 | L4: =SUM(C4:H4)/K4 -> 0.054845485
A5: AT | B5: 2005 | C5: 577836754 | D5: 1575723005 | E5: 762073259 | F5: 1060017068 | G5: 488132036 | H5: 470708917 | K5: 100620644589 | L5: =SUM(C5:H5)/K5 -> 0.049040543
A6: AT | B6: 2006 | C6: 760094123 | D6: 1809024531 | E6: 426131675 | F6: 1031691758 | G6: 539788704 | H6: 441936541 | K6: 108913131868 | L6: =SUM(C6:H6)/K6 -> 0.045987727
A7: AT | B7: 2007 | C7: 585462128 | D7: 1439230344 | E7: 391657587 | F7: 1030841586 | G7: 734584485 | H7: 893944983 | K7: 119387392490 | L7: =SUM(C7:H7)/K7 -> 0.042514716
A8: AT | B8: 2008 | C8: 707118327 | D8: 1195752529 | E8: 321836204 | F8: 1122316434 | G8: 760504255 | H8: 897230750 | K8: 123258767441 | L8: =SUM(C8:H8)/K8 -> 0.040603671
A9: AT | B9: 2009 | C9: 507516418 | D9: 949160956 | E9: 213048001 | F9: 929892110 | G9: 636807159 | H9: 663087502 | K9: 98213743491 | L9: =SUM(C9:H9)/K9 -> 0.039704343
A10: AT | B10: 2010 | C10: 777790773 | D10: 1357254710 | E10: 231317752 | F10: 1068219526 | G10: 773897730 | H10: 741447612 | K10: 115078517863 | L10: =SUM(C10:H10)/K10 -> 0.043013485
A11: AT | B11: 2011 | C11: 842148350 | D11: 1153045756 | E11: 311363108 | F11: 779369155 | G11: 855516038 | H11: 864481109 | K11: 127462352596 | L11: =SUM(C11:H11)/K11 -> 0.037704651
A12: AT | B12: 2012 | C12: 777609377 | D12: 1060802488 | E12: 238886268 | F12: 789811574 | G12: 942752232 | H12: 768345370 | K12: 129678513652 | L12: =SUM(C12:H12)/K12 -> 0.035304286
A13: AT | B13: 2013 | C13: 825036942 | D13: 1030942848 | E13: 274161764 | F13: 1149708436 | G13: 792283150 | H13: 760434903 | K13: 131884592219 | L13: =SUM(C13:H13)/K13 -> 0.0366424
... A241: PT | B241: 2025 | C241: 345747963 | D241: 718725956 | E241: 65855892 | F241: 147241712 | G241: 81760398 | H241: 137576409 | K241: 78967527509 | L241: =SUM(C241:H241)/K241 -> 0.018955998

Sheet wui
A1: quarter | B1: wui_global
A2: 1990Q1 | B2: 12496.47
A3: 1990Q2 | B3: 8769.965
A4: 1990Q3 | B4: 16198.83
A5: 1990Q4 | B5: 11872.27
A6: 1991Q1 | B6: 8223.55
A7: 1991Q2 | B7: 10483.81
A8: 1991Q3 | B8: 6208.322
A9: 1991Q4 | B9: 7314.133
A10: 1992Q1 | B10: 12616.9
A11: 1992Q2 | B11: 7358.835
A12: 1992Q3 | B12: 6777.611
A13: 1992Q4 | B13: 13982.37
... A147: 2026Q2 | B147: 77922.84

Sheet gpr
A1: quarter | B1: gpr_global
A2: 1900Q1
A3: 1900Q2
A4: 1900Q3
A5: 1900Q4
A6: 1901Q1
A7: 1901Q2
A8: 1901Q3
A9: 1901Q4
A10: 1902Q1
A11: 1902Q2
A12: 1902Q3
A13: 1902Q4
... A341: 1984Q4
A342: 1985Q1 | B342: 114.68452
A343: 1985Q2 | B343: 113.32489
A344: 1985Q3 | B344: 106.37467
A345: 1985Q4 | B345: 99.087087
A346: 1986Q1 | B346: 110.92915
A347: 1986Q2 | B347: 120.66578
A348: 1986Q3 | B348: 105.05187
A349: 1986Q4 | B349: 98.77301
A350: 1987Q1 | B350: 95.744629
A351: 1987Q2 | B351: 102.0758
A352: 1987Q3 | B352: 106.66916
A353: 1987Q4 | B353: 102.35615
... A508: 2026Q3 | B508: 142.72554

Sheet epu
A1: quarter | B1: epu_global
A2: 1997Q1 | B2: 74.770187
A3: 1997Q2 | B3: 77.463074
A4: 1997Q3 | B4: 65.491694
A5: 1997Q4 | B5: 95.972339
A6: 1998Q1 | B6: 91.132628
A7: 1998Q2 | B7: 83.346614
A8: 1998Q3 | B8: 122.67404
A9: 1998Q4 | B9: 105.82335
A10: 1999Q1 | B10: 81.105263
A11: 1999Q2 | B11: 69.228681
A12: 1999Q3 | B12: 69.89554
A13: 1999Q4 | B13: 66.469898
... A120: 2026Q3 | B120: 241.69049

Sheet tpu
A1: quarter | B1: tpu_global
A2: 1960Q1 | B2: 14.9493
A3: 1960Q2 | B3: 16.928593
A4: 1960Q3 | B4: 15.502807
A5: 1960Q4 | B5: 16.523557
A6: 1961Q1 | B6: 18.406929
A7: 1961Q2 | B7: 14.928116
A8: 1961Q3 | B8: 17.296939
A9: 1961Q4 | B9: 31.278054
A10: 1962Q1 | B10: 38.76535
A11: 1962Q2 | B11: 31.400813
A12: 1962Q3 | B12: 31.582582
A13: 1962Q4 | B13: 23.523095
... A267: 2026Q2 | B267: 194.8809

Sheet gscpi
A1: quarter | B1: gscpi_global
A2: 1998Q1 | B2: -0.54402118
A3: 1998Q2 | B3: -0.42544361
A4: 1998Q3 | B4: -0.8955413
A5: 1998Q4 | B5: -0.68346173
A6: 1999Q1 | B6: -0.22363105
A7: 1999Q2 | B7: -0.33793265
A8: 1999Q3 | B8: -0.5038114
A9: 1999Q4 | B9: -0.17213884
A10: 2000Q1 | B10: -0.42647369
A11: 2000Q2 | B11: 0.18787682
A12: 2000Q3 | B12: 0.1165019
A13: 2000Q4 | B13: -0.67875301
... A116: 2026Q3 | B116: 0.99940755

Sheet com
A1: quarter | B1: commodity_price_index
A2: 1992Q1 | B2: 47.928102
A3: 1992Q2 | B3: 49.667459
A4: 1992Q3 | B4: 51.140282
A5: 1992Q4 | B5: 49.160205
A6: 1993Q1 | B6: 48.499151
A7: 1993Q2 | B7: 49.773052
A8: 1993Q3 | B8: 48.356852
A9: 1993Q4 | B9: 46.995259
A10: 1994Q1 | B10: 47.720813
A11: 1994Q2 | B11: 49.815667
A12: 1994Q3 | B12: 51.634008
A13: 1994Q4 | B13: 52.456731
... A139: 2026Q2 | B139: 207.79466

Sheet trade_openness
A1: country | B1: year | C1: trade_openness
A2: AT | B2: 2000 | C2: 85.842608
A3: AT | B3: 2001 | C3: 87.996257
A4: AT | B4: 2002 | C4: 87.584494
A5: AT | B5: 2003 | C5: 86.882226
A6: AT | B6: 2004 | C6: 91.47422
A7: AT | B7: 2005 | C7: 94.674755
A8: AT | B8: 2006 | C8: 98.785725
A9: AT | B9: 2007 | C9: 101.36496
A10: AT | B10: 2008 | C10: 102.7437
A11: AT | B11: 2009 | C11: 87.600493
A12: AT | B12: 2010 | C12: 99.644883
A13: AT | B13: 2011 | C13: 105.7751
... A261: PT | B261: 2025 | C261: 86.398877

Sheet population_growth
A1: country | B1: year | C1: population_growth
A2: AT | B2: 2000 | C2: 0.24046665
A3: AT | B3: 2001 | C3: 0.38279939
A4: AT | B4: 2002 | C4: 0.49198046
A5: AT | B5: 2003 | C5: 0.48713389
A6: AT | B6: 2004 | C6: 0.62041313
A7: AT | B7: 2005 | C7: 0.68126725
A8: AT | B8: 2006 | C8: 0.49479778
A9: AT | B9: 2007 | C9: 0.32414654
A10: AT | B10: 2008 | C10: 0.31304144
A11: AT | B11: 2009 | C11: 0.26195319
A12: AT | B12: 2010 | C12: 0.2403943
A13: AT | B13: 2011 | C13: 0.33708084
... A261: PT | B261: 2025 | C261: 1.0250536

Sheet productivity_growth
A1: country | B1: year | C1: productivity_growth
A2: AT | B2: 2001 | C2: 1.3508369
A3: AT | B3: 2002 | C3: 1.7177641
A4: AT | B4: 2003 | C4: 0.96633751
A5: AT | B5: 2004 | C5: 1.769571
A6: AT | B6: 2005 | C6: 2.4975553
A7: AT | B7: 2006 | C7: 2.4475422
A8: AT | B8: 2007 | C8: 2.4949208
A9: AT | B9: 2008 | C9: -0.035978075
A10: AT | B10: 2009 | C10: -0.36049448
A11: AT | B11: 2010 | C11: 1.4405277
A12: AT | B12: 2011 | C12: 0.97418421
A13: AT | B13: 2012 | C13: 1.0581891
... A251: PT | B251: 2025 | C251: -0.015449981

Sheet gdp_per_capita
A1: country | B1: year | C1: gdp_per_capita
A2: AT | B2: 2000 | C2: 31510
A3: AT | B3: 2001 | C3: 31800
A4: AT | B4: 2002 | C4: 32120
A5: AT | B5: 2003 | C5: 32340
A6: AT | B6: 2004 | C6: 32960
A7: AT | B7: 2005 | C7: 33500
A8: AT | B8: 2006 | C8: 34410
A9: AT | B9: 2007 | C9: 35600
A10: AT | B10: 2008 | C10: 36000
A11: AT | B11: 2009 | C11: 34630
A12: AT | B12: 2010 | C12: 35170
A13: AT | B13: 2011 | C13: 36080
... A261: PT | B261: 2025 | C261: 19730

Sheet infl
A1: country | B1: quarter | C1: hicp_index
A2: AT | B2: 2000Q1 | C2: 74.683333
A3: AT | B3: 2000Q2 | C3: 74.83
A4: AT | B4: 2000Q3 | C4: 74.923333
A5: AT | B5: 2000Q4 | C5: 75.64
A6: AT | B6: 2001Q1 | C6: 76.166667
A7: AT | B7: 2001Q2 | C7: 76.843333
A8: AT | B8: 2001Q3 | C8: 76.82
A9: AT | B9: 2001Q4 | C9: 77.146667
A10: AT | B10: 2002Q1 | C10: 77.52
A11: AT | B11: 2002Q2 | C11: 78.07
A12: AT | B12: 2002Q3 | C12: 78.12
A13: AT | B13: 2002Q4 | C13: 78.43
... A1041: PT | B1041: 2025Q4 | C1041: 125.55
